Workbook

Sheet Rate Card Reference (source)
A1: Australia Post MyPost Business — Rate Card Reference
A2: Source: MyPost Business Rates and Savings Guide, July 2026 (official PDF, user-provided). Domestic = Parcel Post (2+ business days). International = International Post Express.
A3: Do not edit this sheet by hand — it is the lookup source for every formula in this workbook. Update it only when Australia Post publishes a new rate card.
A5: DOMESTIC — Parcel Post, up to 5kg (own/AP packaging)
A6: Band | B6: Size | C6: Weight | D6: Zone 1 ($) | E6: Zone 2 ($) | F6: Zone 3 ($)
A7: 0 | B7: Extra Small | C7: 250g | D7: 10.2 | E7: 10.2 | F7: 10.2
A8: 0 | B8: Small | C8: 500g | D8: 11.7 | E8: 11.7 | F8: 11.7
A9: 0 | B9: Medium | C9: 1kg | D9: 16 | E9: 16 | F9: 16
A10: 0 | B10: Large | C10: 3kg | D10: 20.25 | E10: 20.25 | F10: 20.25
A11: 0 | B11: Extra Large | C11: 5kg | D11: 24.45 | E11: 24.45 | F11: 24.45
A12: 1 | B12: Extra Small | C12: 250g | D12: 9.18 | E12: 9.69 | F12: 10.2
A13: 1 | B13: Small | C13: 500g | D13: 10.53 | E13: 11.12 | F13: 11.7
A14: 1 | B14: Medium | C14: 1kg | D14: 14.4 | E14: 15.2 | F14: 16
A15: 1 | B15: Large | C15: 3kg | D15: 18.23 | E15: 19.24 | F15: 20.25
A16: 1 | B16: Extra Large | C16: 5kg | D16: 22.01 | E16: 23.23 | F16: 24.45
A17: 2 | B17: Extra Small | C17: 250g | D17: 7.65 | E17: 8.98 | F17: 10
A18: 2 | B18: Small | C18: 500g | D18: 8.78 | E18: 10.3 | F18: 11.47
... A36: 5 | B36: Extra Large | C36: 5kg | D36: 14.67 | E36: 19.56 | F36: 23.23
A39: INTERNATIONAL EXPRESS — key destinations
A40: Band | B40: Weight | C40: NZ Zone1 ($) | D40: China Zone2 ($) | E40: USA&Canada Zone3 ($) | F40: UK&Ireland Zone4 ($)
A41: 0 | B41: Up to 250g | C41: 17.9 | D41: 20.6 | E41: 23.05 | F41: 28.4
A42: 0 | B42: 251g-500g | C42: 21.6 | D42: 26.85 | E42: 29.95 | F42: 35.55
A43: 0 | B43: 501g-1kg | C43: 29 | D43: 39.4 | E43: 43.6 | F43: 49.9
A44: 0 | B44: 1.001kg-1.5kg | C44: 36.4 | D44: 51.95 | E44: 57.4 | F44: 64.2
A45: 0 | B45: 1.501kg-2kg | C45: 43.8 | D45: 64.5 | E45: 71.1 | F45: 78.5
A46: 1 | B46: Up to 250g | C46: 17.01 | D46: 19.57 | E46: 21.9 | F46: 26.98
A47: 1 | B47: 251g-500g | C47: 20.52 | D47: 25.51 | E47: 28.45 | F47: 33.77
A48: 1 | B48: 501g-1kg | C48: 27.55 | D48: 37.43 | E48: 41.42 | F48: 47.41
A49: 1 | B49: 1.001kg-1.5kg | C49: 34.58 | D49: 49.35 | E49: 54.53 | F49: 60.99
A50: 1 | B50: 1.501kg-2kg | C50: 41.61 | D50: 61.28 | E50: 67.55 | F50: 74.58
A51: 2 | B51: Up to 250g | C51: 14.32 | D51: 17.51 | E51: 19.59 | F51: 24.14
A52: 2 | B52: 251g-500g | C52: 17.28 | D52: 22.82 | E52: 25.46 | F52: 30.22
... A70: 5 | B70: 1.501kg-2kg | C70: 28.47 | D70: 49.99 | E70: 55.1 | F70: 60.84
A73: INTERNATIONAL EXPRESS — other destinations
A74: Band | B74: Weight | C74: Rest of Asia ($) | D74: Pacific Islands ($) | E74: Major Europe ($) | F74: Rest of World 1 ($) | G74: Rest of World 2 ($)
A75: 0 | B75: Up to 250g | C75: 20.6 | D75: 20.6 | E75: 28.4 | F75: 28.4 | G75: 34.45
A76: 0 | B76: 251g-500g | C76: 26.85 | D76: 26.85 | E76: 35.55 | F76: 35.55 | G76: 43.8
A77: 0 | B77: 501g-1kg | C77: 39.4 | D77: 39.4 | E77: 49.9 | F77: 49.9 | G77: 62.5
A78: 0 | B78: 1.001kg-1.5kg | C78: 51.95 | D78: 51.95 | E78: 64.2 | F78: 64.2 | G78: 81.15
A79: 0 | B79: 1.501kg-2kg | C79: 64.5 | D79: 64.5 | E79: 78.5 | F79: 78.5 | G79: 99.8
...

Sheet Delivery Details and calculatio
A1: Delivery Rates — Live Calculation
A3: Your current MyPost Business Band: | B3: 1 | C3: <- EDIT THIS CELL when your band changes (check MyPost Business > Send and Save tab). Everything below recalculates automatically.
A6: DOMESTIC (Parcel Post, up to 5kg)
A7: Size | B7: Weight | C7: Zone 1 | D7: Zone 2 | E7: Zone 3
A8: Extra Small | B8: 250g | C8: =INDEX('Rate Card Reference (source)'!$D$7:$D$36,MATCH(1,('Rate Card Reference (source)'!$A$7:$A$36=$B$3)*('Rate Card Reference (source)'!$B$7:$B$36=$A8),0)) -> 9.18 | D8: =INDEX('Rate Card Reference (source)'!$E$7:$E$36,MATCH(1,('Rate Card Reference (source)'!$A$7:$A$36=$B$3)*('Rate Card Reference (source)'!$B$7:$B$36=$A8),0)) -> 9.69 | E8: =INDEX('Rate Card Reference (source)'!$F$7:$F$36,MATCH(1,('Rate Card Reference (source)'!$A$7:$A$36=$B$3)*('Rate Card Reference (source)'!$B$7:$B$36=$A8),0)) -> 10.2
A9: Small | B9: 500g | C9: =INDEX('Rate Card Reference (source)'!$D$7:$D$36,MATCH(1,('Rate Card Reference (source)'!$A$7:$A$36=$B$3)*('Rate Card Reference (source)'!$B$7:$B$36=$A9),0)) -> 10.53 | D9: =INDEX('Rate Card Reference (source)'!$E$7:$E$36,MATCH(1,('Rate Card Reference (source)'!$A$7:$A$36=$B$3)*('Rate Card Reference (source)'!$B$7:$B$36=$A9),0)) -> 11.12 | E9: =INDEX('Rate Card Reference (source)'!$F$7:$F$36,MATCH(1,('Rate Card Reference (source)'!$A$7:$A$36=$B$3)*('Rate Card Reference (source)'!$B$7:$B$36=$A9),0)) -> 11.7
A10: Medium | B10: 1kg | C10: =INDEX('Rate Card Reference (source)'!$D$7:$D$36,MATCH(1,('Rate Card Reference (source)'!$A$7:$A$36=$B$3)*('Rate Card Reference (source)'!$B$7:$B$36=$A10),0)) -> 14.4 | D10: =INDEX('Rate Card Reference (source)'!$E$7:$E$36,MATCH(1,('Rate Card Reference (source)'!$A$7:$A$36=$B$3)*('Rate Card Reference (source)'!$B$7:$B$36=$A10),0)) -> 15.2 | E10: =INDEX('Rate Card Reference (source)'!$F$7:$F$36,MATCH(1,('Rate Card Reference (source)'!$A$7:$A$36=$B$3)*('Rate Card Reference (source)'!$B$7:$B$36=$A10),0)) -> 16
A11: Large | B11: 3kg | C11: =INDEX('Rate Card Reference (source)'!$D$7:$D$36,MATCH(1,('Rate Card Reference (source)'!$A$7:$A$36=$B$3)*('Rate Card Reference (source)'!$B$7:$B$36=$A11),0)) -> 18.23 | D11: =INDEX('Rate Card Reference (source)'!$E$7:$E$36,MATCH(1,('Rate Card Reference (source)'!$A$7:$A$36=$B$3)*('Rate Card Reference (source)'!$B$7:$B$36=$A11),0)) -> 19.24 | E11: =INDEX('Rate Card Reference (source)'!$F$7:$F$36,MATCH(1,('Rate Card Reference (source)'!$A$7:$A$36=$B$3)*('Rate Card Reference (source)'!$B$7:$B$36=$A11),0)) -> 20.25
A12: Extra Large | B12: 5kg | C12: =INDEX('Rate Card Reference (source)'!$D$7:$D$36,MATCH(1,('Rate Card Reference (source)'!$A$7:$A$36=$B$3)*('Rate Card Reference (source)'!$B$7:$B$36=$A12),0)) -> 22.01 | D12: =INDEX('Rate Card Reference (source)'!$E$7:$E$36,MATCH(1,('Rate Card Reference (source)'!$A$7:$A$36=$B$3)*('Rate Card Reference (source)'!$B$7:$B$36=$A12),0)) -> 23.23 | E12: =INDEX('Rate Card Reference (source)'!$F$7:$F$36,MATCH(1,('Rate Card Reference (source)'!$A$7:$A$36=$B$3)*('Rate Card Reference (source)'!$B$7:$B$36=$A12),0)) -> 24.45
A15: INTERNATIONAL EXPRESS — key destinations
A16: Weight | B16: NZ (Zone1) | C16: China (Zone2) | D16: USA&Canada (Zone3) | E16: UK&Ireland (Zone4)
A17: Up to 250g | B17: =INDEX('Rate Card Reference (source)'!$C$41:$C$70,MATCH(1,('Rate Card Reference (source)'!$A$41:$A$70=$B$3)*('Rate Card Reference (source)'!$B$41:$B$70=$A17),0)) -> 17.01 | C17: =INDEX('Rate Card Reference (source)'!$D$41:$D$70,MATCH(1,('Rate Card Reference (source)'!$A$41:$A$70=$B$3)*('Rate Card Reference (source)'!$B$41:$B$70=$A17),0)) -> 19.57 | D17: =INDEX('Rate Card Reference (source)'!$E$41:$E$70,MATCH(1,('Rate Card Reference (source)'!$A$41:$A$70=$B$3)*('Rate Card Reference (source)'!$B$41:$B$70=$A17),0)) -> 21.9 | E17: =INDEX('Rate Card Reference (source)'!$F$41:$F$70,MATCH(1,('Rate Card Reference (source)'!$A$41:$A$70=$B$3)*('Rate Card Reference (source)'!$B$41:$B$70=$A17),0)) -> 26.98
A18: 251g-500g | B18: =INDEX('Rate Card Reference (source)'!$C$41:$C$70,MATCH(1,('Rate Card Reference (source)'!$A$41:$A$70=$B$3)*('Rate Card Reference (source)'!$B$41:$B$70=$A18),0)) -> 20.52 | C18: =INDEX('Rate Card Reference (source)'!$D$41:$D$70,MATCH(1,('Rate Card Reference (source)'!$A$41:$A$70=$B$3)*('Rate Card Reference (source)'!$B$41:$B$70=$A18),0)) -> 25.51 | D18: =INDEX('Rate Card Reference (source)'!$E$41:$E$70,MATCH(1,('Rate Card Reference (source)'!$A$41:$A$70=$B$3)*('Rate Card Reference (source)'!$B$41:$B$70=$A18),0)) -> 28.45 | E18: =INDEX('Rate Card Reference (source)'!$F$41:$F$70,MATCH(1,('Rate Card Reference (source)'!$A$41:$A$70=$B$3)*('Rate Card Reference (source)'!$B$41:$B$70=$A18),0)) -> 33.77
A19: 501g-1kg | B19: =INDEX('Rate Card Reference (source)'!$C$41:$C$70,MATCH(1,('Rate Card Reference (source)'!$A$41:$A$70=$B$3)*('Rate Card Reference (source)'!$B$41:$B$70=$A19),0)) -> 27.55 | C19: =INDEX('Rate Card Reference (source)'!$D$41:$D$70,MATCH(1,('Rate Card Reference (source)'!$A$41:$A$70=$B$3)*('Rate Card Reference (source)'!$B$41:$B$70=$A19),0)) -> 37.43 | D19: =INDEX('Rate Card Reference (source)'!$E$41:$E$70,MATCH(1,('Rate Card Reference (source)'!$A$41:$A$70=$B$3)*('Rate Card Reference (source)'!$B$41:$B$70=$A19),0)) -> 41.42 | E19: =INDEX('Rate Card Reference (source)'!$F$41:$F$70,MATCH(1,('Rate Card Reference (source)'!$A$41:$A$70=$B$3)*('Rate Card Reference (source)'!$B$41:$B$70=$A19),0)) -> 47.41
A20: 1.001kg-1.5kg | B20: =INDEX('Rate Card Reference (source)'!$C$41:$C$70,MATCH(1,('Rate Card Reference (source)'!$A$41:$A$70=$B$3)*('Rate Card Reference (source)'!$B$41:$B$70=$A20),0)) -> 34.58 | C20: =INDEX('Rate Card Reference (source)'!$D$41:$D$70,MATCH(1,('Rate Card Reference (source)'!$A$41:$A$70=$B$3)*('Rate Card Reference (source)'!$B$41:$B$70=$A20),0)) -> 49.35 | D20: =INDEX('Rate Card Reference (source)'!$E$41:$E$70,MATCH(1,('Rate Card Reference (source)'!$A$41:$A$70=$B$3)*('Rate Card Reference (source)'!$B$41:$B$70=$A20),0)) -> 54.53 | E20: =INDEX('Rate Card Reference (source)'!$F$41:$F$70,MATCH(1,('Rate Card Reference (source)'!$A$41:$A$70=$B$3)*('Rate Card Reference (source)'!$B$41:$B$70=$A20),0)) -> 60.99
A21: 1.501kg-2kg | B21: =INDEX('Rate Card Reference (source)'!$C$41:$C$70,MATCH(1,('Rate Card Reference (source)'!$A$41:$A$70=$B$3)*('Rate Card Reference (source)'!$B$41:$B$70=$A21),0)) -> 41.61 | C21: =INDEX('Rate Card Reference (source)'!$D$41:$D$70,MATCH(1,('Rate Card Reference (source)'!$A$41:$A$70=$B$3)*('Rate Card Reference (source)'!$B$41:$B$70=$A21),0)) -> 61.28 | D21: =INDEX('Rate Card Reference (source)'!$E$41:$E$70,MATCH(1,('Rate Card Reference (source)'!$A$41:$A$70=$B$3)*('Rate Card Reference (source)'!$B$41:$B$70=$A21),0)) -> 67.55 | E21: =INDEX('Rate Card Reference (source)'!$F$41:$F$70,MATCH(1,('Rate Card Reference (source)'!$A$41:$A$70=$B$3)*('Rate Card Reference (source)'!$B$41:$B$70=$A21),0)) -> 74.58
A24: INTERNATIONAL EXPRESS — other destinations
A25: Weight | B25: Rest of Asia | C25: Pacific Islands | D25: Major Europe | E25: Rest of World 1 | F25: Rest of World 2
A26: Up to 250g | B26: =INDEX('Rate Card Reference (source)'!$C$75:$C$104,MATCH(1,('Rate Card Reference (source)'!$A$75:$A$104=$B$3)*('Rate Card Reference (source)'!$B$75:$B$104=$A26),0)) -> 19.57 | C26: =INDEX('Rate Card Reference (source)'!$D$75:$D$104,MATCH(1,('Rate Card Reference (source)'!$A$75:$A$104=$B$3)*('Rate Card Reference (source)'!$B$75:$B$104=$A26),0)) -> 19.57 | D26: =INDEX('Rate Card Reference (source)'!$E$75:$E$104,MATCH(1,('Rate Card Reference (source)'!$A$75:$A$104=$B$3)*('Rate Card Reference (source)'!$B$75:$B$104=$A26),0)) -> 26.98 | E26: =INDEX('Rate Card Reference (source)'!$F$75:$F$104,MATCH(1,('Rate Card Reference (source)'!$A$75:$A$104=$B$3)*('Rate Card Reference (source)'!$B$75:$B$104=$A26),0)) -> 26.98 | F26: =INDEX('Rate Card Reference (source)'!$G$75:$G$104,MATCH(1,('Rate Card Reference (source)'!$A$75:$A$104=$B$3)*('Rate Card Reference (source)'!$B$75:$B$104=$A26),0)) -> 32.73
A27: 251g-500g | B27: =INDEX('Rate Card Reference (source)'!$C$75:$C$104,MATCH(1,('Rate Card Reference (source)'!$A$75:$A$104=$B$3)*('Rate Card Reference (source)'!$B$75:$B$104=$A27),0)) -> 25.51 | C27: =INDEX('Rate Card Reference (source)'!$D$75:$D$104,MATCH(1,('Rate Card Reference (source)'!$A$75:$A$104=$B$3)*('Rate Card Reference (source)'!$B$75:$B$104=$A27),0)) -> 25.51 | D27: =INDEX('Rate Card Reference (source)'!$E$75:$E$104,MATCH(1,('Rate Card Reference (source)'!$A$75:$A$104=$B$3)*('Rate Card Reference (source)'!$B$75:$B$104=$A27),0)) -> 33.77 | E27: =INDEX('Rate Card Reference (source)'!$F$75:$F$104,MATCH(1,('Rate Card Reference (source)'!$A$75:$A$104=$B$3)*('Rate Card Reference (source)'!$B$75:$B$104=$A27),0)) -> 33.77 | F27: =INDEX('Rate Card Reference (source)'!$G$75:$G$104,MATCH(1,('Rate Card Reference (source)'!$A$75:$A$104=$B$3)*('Rate Card Reference (source)'!$B$75:$B$104=$A27),0)) -> 41.61
A28: 501g-1kg | B28: =INDEX('Rate Card Reference (source)'!$C$75:$C$104,MATCH(1,('Rate Card Reference (source)'!$A$75:$A$104=$B$3)*('Rate Card Reference (source)'!$B$75:$B$104=$A28),0)) -> 37.43 | C28: =INDEX('Rate Card Reference (source)'!$D$75:$D$104,MATCH(1,('Rate Card Reference (source)'!$A$75:$A$104=$B$3)*('Rate Card Reference (source)'!$B$75:$B$104=$A28),0)) -> 37.43 | D28: =INDEX('Rate Card Reference (source)'!$E$75:$E$104,MATCH(1,('Rate Card Reference (source)'!$A$75:$A$104=$B$3)*('Rate Card Reference (source)'!$B$75:$B$104=$A28),0)) -> 47.41 | E28: =INDEX('Rate Card Reference (source)'!$F$75:$F$104,MATCH(1,('Rate Card Reference (source)'!$A$75:$A$104=$B$3)*('Rate Card Reference (source)'!$B$75:$B$104=$A28),0)) -> 47.41 | F28: =INDEX('Rate Card Reference (source)'!$G$75:$G$104,MATCH(1,('Rate Card Reference (source)'!$A$75:$A$104=$B$3)*('Rate Card Reference (source)'!$B$75:$B$104=$A28),0)) -> 59.38
A29: 1.001kg-1.5kg | B29: =INDEX('Rate Card Reference (source)'!$C$75:$C$104,MATCH(1,('Rate Card Reference (source)'!$A$75:$A$104=$B$3)*('Rate Card Reference (source)'!$B$75:$B$104=$A29),0)) -> 49.35 | C29: =INDEX('Rate Card Reference (source)'!$D$75:$D$104,MATCH(1,('Rate Card Reference (source)'!$A$75:$A$104=$B$3)*('Rate Card Reference (source)'!$B$75:$B$104=$A29),0)) -> 49.35 | D29: =INDEX('Rate Card Reference (source)'!$E$75:$E$104,MATCH(1,('Rate Card Reference (source)'!$A$75:$A$104=$B$3)*('Rate Card Reference (source)'!$B$75:$B$104=$A29),0)) -> 60.99 | E29: =INDEX('Rate Card Reference (source)'!$F$75:$F$104,MATCH(1,('Rate Card Reference (source)'!$A$75:$A$104=$B$3)*('Rate Card Reference (source)'!$B$75:$B$104=$A29),0)) -> 60.99 | F29: =INDEX('Rate Card Reference (source)'!$G$75:$G$104,MATCH(1,('Rate Card Reference (source)'!$A$75:$A$104=$B$3)*('Rate Card Reference (source)'!$B$75:$B$104=$A29),0)) -> 77.09
A30: 1.501kg-2kg | B30: =INDEX('Rate Card Reference (source)'!$C$75:$C$104,MATCH(1,('Rate Card Reference (source)'!$A$75:$A$104=$B$3)*('Rate Card Reference (source)'!$B$75:$B$104=$A30),0)) -> 61.28 | C30: =INDEX('Rate Card Reference (source)'!$D$75:$D$104,MATCH(1,('Rate Card Reference (source)'!$A$75:$A$104=$B$3)*('Rate Card Reference (source)'!$B$75:$B$104=$A30),0)) -> 61.28 | D30: =INDEX('Rate Card Reference (source)'!$E$75:$E$104,MATCH(1,('Rate Card Reference (source)'!$A$75:$A$104=$B$3)*('Rate Card Reference (source)'!$B$75:$B$104=$A30),0)) -> 74.58 | E30: =INDEX('Rate Card Reference (source)'!$F$75:$F$104,MATCH(1,('Rate Card Reference (source)'!$A$75:$A$104=$B$3)*('Rate Card Reference (source)'!$B$75:$B$104=$A30),0)) -> 74.58 | F30: =INDEX('Rate Card Reference (source)'!$G$75:$G$104,MATCH(1,('Rate Card Reference (source)'!$A$75:$A$104=$B$3)*('Rate Card Reference (source)'!$B$75:$B$104=$A30),0)) -> 94.81

Sheet Country Master List
A1: Country Shipping Rates (International Post Express)
A2: Rates pull live from 'Delivery Details and calculatio' at your current Band (set on that sheet). 'Asia Pacific' group uses the Rest of Asia rate for all countries in that group (Australia Post prices some Pacific Island nations marginally differently at Band 2+ - under $1 difference - check the Rate Card Reference sheet if shipping high volumes to Pacific Islands specifically).
A4: Country | B4: Zone | C4: Group | D4: Up to 250g | E4: 251g-500g | F4: 501g-1kg | G4: 1.001kg-1.5kg | H4: 1.501kg-2kg
A5: Afghanistan | B5: 5 | C5: Rest of World | D5: ='Delivery Details and calculatio'!$F$26 -> 32.73 | E5: ='Delivery Details and calculatio'!$F$27 -> 41.61 | F5: ='Delivery Details and calculatio'!$F$28 -> 59.38 | G5: ='Delivery Details and calculatio'!$F$29 -> 77.09 | H5: ='Delivery Details and calculatio'!$F$30 -> 94.81
A6: Albania | B6: 4 | C6: UK & Europe | D6: ='Delivery Details and calculatio'!$D$26 -> 26.98 | E6: ='Delivery Details and calculatio'!$D$27 -> 33.77 | F6: ='Delivery Details and calculatio'!$D$28 -> 47.41 | G6: ='Delivery Details and calculatio'!$D$29 -> 60.99 | H6: ='Delivery Details and calculatio'!$D$30 -> 74.58
A7: Algeria | B7: 5 | C7: Rest of World | D7: ='Delivery Details and calculatio'!$F$26 -> 32.73 | E7: ='Delivery Details and calculatio'!$F$27 -> 41.61 | F7: ='Delivery Details and calculatio'!$F$28 -> 59.38 | G7: ='Delivery Details and calculatio'!$F$29 -> 77.09 | H7: ='Delivery Details and calculatio'!$F$30 -> 94.81
A8: American Samoa | B8: 2 | C8: Asia Pacific | D8: ='Delivery Details and calculatio'!$B$26 -> 19.57 | E8: ='Delivery Details and calculatio'!$B$27 -> 25.51 | F8: ='Delivery Details and calculatio'!$B$28 -> 37.43 | G8: ='Delivery Details and calculatio'!$B$29 -> 49.35 | H8: ='Delivery Details and calculatio'!$B$30 -> 61.28
A9: Andorra | B9: 4 | C9: UK & Europe | D9: ='Delivery Details and calculatio'!$D$26 -> 26.98 | E9: ='Delivery Details and calculatio'!$D$27 -> 33.77 | F9: ='Delivery Details and calculatio'!$D$28 -> 47.41 | G9: ='Delivery Details and calculatio'!$D$29 -> 60.99 | H9: ='Delivery Details and calculatio'!$D$30 -> 74.58
A10: Angola | B10: 5 | C10: Rest of World | D10: ='Delivery Details and calculatio'!$F$26 -> 32.73 | E10: ='Delivery Details and calculatio'!$F$27 -> 41.61 | F10: ='Delivery Details and calculatio'!$F$28 -> 59.38 | G10: ='Delivery Details and calculatio'!$F$29 -> 77.09 | H10: ='Delivery Details and calculatio'!$F$30 -> 94.81
A11: Anguilla | B11: 5 | C11: Rest of World | D11: ='Delivery Details and calculatio'!$F$26 -> 32.73 | E11: ='Delivery Details and calculatio'!$F$27 -> 41.61 | F11: ='Delivery Details and calculatio'!$F$28 -> 59.38 | G11: ='Delivery Details and calculatio'!$F$29 -> 77.09 | H11: ='Delivery Details and calculatio'!$F$30 -> 94.81
A12: Antigua and Barbuda | B12: 5 | C12: Rest of World | D12: ='Delivery Details and calculatio'!$F$26 -> 32.73 | E12: ='Delivery Details and calculatio'!$F$27 -> 41.61 | F12: ='Delivery Details and calculatio'!$F$28 -> 59.38 | G12: ='Delivery Details and calculatio'!$F$29 -> 77.09 | H12: ='Delivery Details and calculatio'!$F$30 -> 94.81
A13: Argentina | B13: 5 | C13: Rest of World | D13: ='Delivery Details and calculatio'!$F$26 -> 32.73 | E13: ='Delivery Details and calculatio'!$F$27 -> 41.61 | F13: ='Delivery Details and calculatio'!$F$28 -> 59.38 | G13: ='Delivery Details and calculatio'!$F$29 -> 77.09 | H13: ='Delivery Details and calculatio'!$F$30 -> 94.81
A14: Armenia | B14: 5 | C14: Rest of World | D14: ='Delivery Details and calculatio'!$F$26 -> 32.73 | E14: ='Delivery Details and calculatio'!$F$27 -> 41.61 | F14: ='Delivery Details and calculatio'!$F$28 -> 59.38 | G14: ='Delivery Details and calculatio'!$F$29 -> 77.09 | H14: ='Delivery Details and calculatio'!$F$30 -> 94.81
A15: Aruba | B15: 5 | C15: Rest of World | D15: ='Delivery Details and calculatio'!$F$26 -> 32.73 | E15: ='Delivery Details and calculatio'!$F$27 -> 41.61 | F15: ='Delivery Details and calculatio'!$F$28 -> 59.38 | G15: ='Delivery Details and calculatio'!$F$29 -> 77.09 | H15: ='Delivery Details and calculatio'!$F$30 -> 94.81
A16: Austria | B16: 4 | C16: UK & Europe | D16: ='Delivery Details and calculatio'!$D$26 -> 26.98 | E16: ='Delivery Details and calculatio'!$D$27 -> 33.77 | F16: ='Delivery Details and calculatio'!$D$28 -> 47.41 | G16: ='Delivery Details and calculatio'!$D$29 -> 60.99 | H16: ='Delivery Details and calculatio'!$D$30 -> 74.58
A17: Azerbaijan | B17: 5 | C17: Rest of World | D17: ='Delivery Details and calculatio'!$F$26 -> 32.73 | E17: ='Delivery Details and calculatio'!$F$27 -> 41.61 | F17: ='Delivery Details and calculatio'!$F$28 -> 59.38 | G17: ='Delivery Details and calculatio'!$F$29 -> 77.09 | H17: ='Delivery Details and calculatio'!$F$30 -> 94.81
A18: Bahamas | B18: 5 | C18: Rest of World | D18: ='Delivery Details and calculatio'!$F$26 -> 32.73 | E18: ='Delivery Details and calculatio'!$F$27 -> 41.61 | F18: ='Delivery Details and calculatio'!$F$28 -> 59.38 | G18: ='Delivery Details and calculatio'!$F$29 -> 77.09 | H18: ='Delivery Details and calculatio'!$F$30 -> 94.81
A19: Bahrain | B19: 5 | C19: Rest of World | D19: ='Delivery Details and calculatio'!$F$26 -> 32.73 | E19: ='Delivery Details and calculatio'!$F$27 -> 41.61 | F19: ='Delivery Details and calculatio'!$F$28 -> 59.38 | G19: ='Delivery Details and calculatio'!$F$29 -> 77.09 | H19: ='Delivery Details and calculatio'!$F$30 -> 94.81
A20: Bangladesh | B20: 2 | C20: Asia Pacific | D20: ='Delivery Details and calculatio'!$B$26 -> 19.57 | E20: ='Delivery Details and calculatio'!$B$27 -> 25.51 | F20: ='Delivery Details and calculatio'!$B$28 -> 37.43 | G20: ='Delivery Details and calculatio'!$B$29 -> 49.35 | H20: ='Delivery Details and calculatio'!$B$30 -> 61.28
A21: Barbados | B21: 5 | C21: Rest of World | D21: ='Delivery Details and calculatio'!$F$26 -> 32.73 | E21: ='Delivery Details and calculatio'!$F$27 -> 41.61 | F21: ='Delivery Details and calculatio'!$F$28 -> 59.38 | G21: ='Delivery Details and calculatio'!$F$29 -> 77.09 | H21: ='Delivery Details and calculatio'!$F$30 -> 94.81
A22: Belarus | B22: 5 | C22: Rest of World | D22: ='Delivery Details and calculatio'!$F$26 -> 32.73 | E22: ='Delivery Details and calculatio'!$F$27 -> 41.61 | F22: ='Delivery Details and calculatio'!$F$28 -> 59.38 | G22: ='Delivery Details and calculatio'!$F$29 -> 77.09 | H22: ='Delivery Details and calculatio'!$F$30 -> 94.81
A23: Belgium | B23: 4 | C23: UK & Europe | D23: ='Delivery Details and calculatio'!$D$26 -> 26.98 | E23: ='Delivery Details and calculatio'!$D$27 -> 33.77 | F23: ='Delivery Details and calculatio'!$D$28 -> 47.41 | G23: ='Delivery Details and calculatio'!$D$29 -> 60.99 | H23: ='Delivery Details and calculatio'!$D$30 -> 74.58
A24: Belize | B24: 5 | C24: Rest of World | D24: ='Delivery Details and calculatio'!$F$26 -> 32.73 | E24: ='Delivery Details and calculatio'!$F$27 -> 41.61 | F24: ='Delivery Details and calculatio'!$F$28 -> 59.38 | G24: ='Delivery Details and calculatio'!$F$29 -> 77.09 | H24: ='Delivery Details and calculatio'!$F$30 -> 94.81
A25: Benin | B25: 5 | C25: Rest of World | D25: ='Delivery Details and calculatio'!$F$26 -> 32.73 | E25: ='Delivery Details and calculatio'!$F$27 -> 41.61 | F25: ='Delivery Details and calculatio'!$F$28 -> 59.38 | G25: ='Delivery Details and calculatio'!$F$29 -> 77.09 | H25: ='Delivery Details and calculatio'!$F$30 -> 94.81
A26: Bermuda | B26: 5 | C26: Rest of World | D26: ='Delivery Details and calculatio'!$F$26 -> 32.73 | E26: ='Delivery Details and calculatio'!$F$27 -> 41.61 | F26: ='Delivery Details and calculatio'!$F$28 -> 59.38 | G26: ='Delivery Details and calculatio'!$F$29 -> 77.09 | H26: ='Delivery Details and calculatio'!$F$30 -> 94.81
A27: Bhutan | B27: 5 | C27: Rest of World | D27: ='Delivery Details and calculatio'!$F$26 -> 32.73 | E27: ='Delivery Details and calculatio'!$F$27 -> 41.61 | F27: ='Delivery Details and calculatio'!$F$28 -> 59.38 | G27: ='Delivery Details and calculatio'!$F$29 -> 77.09 | H27: ='Delivery Details and calculatio'!$F$30 -> 94.81
A28: Bolivia | B28: 5 | C28: Rest of World | D28: ='Delivery Details and calculatio'!$F$26 -> 32.73 | E28: ='Delivery Details and calculatio'!$F$27 -> 41.61 | F28: ='Delivery Details and calculatio'!$F$28 -> 59.38 | G28: ='Delivery Details and calculatio'!$F$29 -> 77.09 | H28: ='Delivery Details and calculatio'!$F$30 -> 94.81
A29: Bonaire, Eustatius and Saba | B29: 5 | C29: Rest of World | D29: ='Delivery Details and calculatio'!$F$26 -> 32.73 | E29: ='Delivery Details and calculatio'!$F$27 -> 41.61 | F29: ='Delivery Details and calculatio'!$F$28 -> 59.38 | G29: ='Delivery Details and calculatio'!$F$29 -> 77.09 | H29: ='Delivery Details and calculatio'!$F$30 -> 94.81
A30: Bosnia and Herzegovina | B30: 4 | C30: UK & Europe | D30: ='Delivery Details and calculatio'!$D$26 -> 26.98 | E30: ='Delivery Details and calculatio'!$D$27 -> 33.77 | F30: ='Delivery Details and calculatio'!$D$28 -> 47.41 | G30: ='Delivery Details and calculatio'!$D$29 -> 60.99 | H30: ='Delivery Details and calculatio'!$D$30 -> 74.58
A31: Botswana | B31: 5 | C31: Rest of World | D31: ='Delivery Details and calculatio'!$F$26 -> 32.73 | E31: ='Delivery Details and calculatio'!$F$27 -> 41.61 | F31: ='Delivery Details and calculatio'!$F$28 -> 59.38 | G31: ='Delivery Details and calculatio'!$F$29 -> 77.09 | H31: ='Delivery Details and calculatio'!$F$30 -> 94.81
A32: Brazil | B32: 4 | C32: UK & Europe | D32: ='Delivery Details and calculatio'!$D$26 -> 26.98 | E32: ='Delivery Details and calculatio'!$D$27 -> 33.77 | F32: ='Delivery Details and calculatio'!$D$28 -> 47.41 | G32: ='Delivery Details and calculatio'!$D$29 -> 60.99 | H32: ='Delivery Details and calculatio'!$D$30 -> 74.58
A33: British Indian Ocean Territory | B33: 5 | C33: Rest of World | D33: ='Delivery Details and calculatio'!$F$26 -> 32.73 | E33: ='Delivery Details and calculatio'!$F$27 -> 41.61 | F33: ='Delivery Details and calculatio'!$F$28 -> 59.38 | G33: ='Delivery Details and calculatio'!$F$29 -> 77.09 | H33: ='Delivery Details and calculatio'!$F$30 -> 94.81
A34: Brunei Darussalam | B34: 2 | C34: Asia Pacific | D34: ='Delivery Details and calculatio'!$B$26 -> 19.57 | E34: ='Delivery Details and calculatio'!$B$27 -> 25.51 | F34: ='Delivery Details and calculatio'!$B$28 -> 37.43 | G34: ='Delivery Details and calculatio'!$B$29 -> 49.35 | H34: ='Delivery Details and calculatio'!$B$30 -> 61.28
A35: Bulgaria | B35: 4 | C35: UK & Europe | D35: ='Delivery Details and calculatio'!$D$26 -> 26.98 | E35: ='Delivery Details and calculatio'!$D$27 -> 33.77 | F35: ='Delivery Details and calculatio'!$D$28 -> 47.41 | G35: ='Delivery Details and calculatio'!$D$29 -> 60.99 | H35: ='Delivery Details and calculatio'!$D$30 -> 74.58
A36: Burkina Faso | B36: 5 | C36: Rest of World | D36: ='Delivery Details and calculatio'!$F$26 -> 32.73 | E36: ='Delivery Details and calculatio'!$F$27 -> 41.61 | F36: ='Delivery Details and calculatio'!$F$28 -> 59.38 | G36: ='Delivery Details and calculatio'!$F$29 -> 77.09 | H36: ='Delivery Details and calculatio'!$F$30 -> 94.81
A37: Burundi | B37: 5 | C37: Rest of World | D37: ='Delivery Details and calculatio'!$F$26 -> 32.73 | E37: ='Delivery Details and calculatio'!$F$27 -> 41.61 | F37: ='Delivery Details and calculatio'!$F$28 -> 59.38 | G37: ='Delivery Details and calculatio'!$F$29 -> 77.09 | H37: ='Delivery Details and calculatio'!$F$30 -> 94.81
A38: Cabo Verde (formerly Cape Verde) | B38: 5 | C38: Rest of World | D38: ='Delivery Details and calculatio'!$F$26 -> 32.73 | E38: ='Delivery Details and calculatio'!$F$27 -> 41.61 | F38: ='Delivery Details and calculatio'!$F$28 -> 59.38 | G38: ='Delivery Details and calculatio'!$F$29 -> 77.09 | H38: ='Delivery Details and calculatio'!$F$30 -> 94.81
A39: Cambodia | B39: 2 | C39: Asia Pacific | D39: ='Delivery Details and calculatio'!$B$26 -> 19.57 | E39: ='Delivery Details and calculatio'!$B$27 -> 25.51 | F39: ='Delivery Details and calculatio'!$B$28 -> 37.43 | G39: ='Delivery Details and calculatio'!$B$29 -> 49.35 | H39: ='Delivery Details and calculatio'!$B$30 -> 61.28
A40: Cameroon | B40: 5 | C40: Rest of World | D40: ='Delivery Details and calculatio'!$F$26 -> 32.73 | E40: ='Delivery Details and calculatio'!$F$27 -> 41.61 | F40: ='Delivery Details and calculatio'!$F$28 -> 59.38 | G40: ='Delivery Details and calculatio'!$F$29 -> 77.09 | H40: ='Delivery Details and calculatio'!$F$30 -> 94.81
A41: Canada | B41: 3 | C41: USA & Canada | D41: ='Delivery Details and calculatio'!$D$17 -> 21.9 | E41: ='Delivery Details and calculatio'!$D$18 -> 28.45 | F41: ='Delivery Details and calculatio'!$D$19 -> 41.42 | G41: ='Delivery Details and calculatio'!$D$20 -> 54.53 | H41: ='Delivery Details and calculatio'!$D$21 -> 67.55
...

Sheet Product Grams
A1: Product Weights (for postage size selection)
A3: Product Name | B3: Variation | C3: Gram Weight
A4: Moringa | B4: Moringa | C4: 100g
C5: 200g
A6: Dried Curry Leaves | B6: Dried Curry Leaves | C6: 30g
A7: Darjeeling Black Tea | B7: Darjeeling Black Tea | C7: 100g
A8: Combo pack | B8: Combo pack | C8: 100g + 30g
A9: Soap | B9: Soap | C9: 95g
A10: Moringa + Soap | B10: Moringa + Soap | C10: 100g + 95

Sheet Product Pricing
A1: Product Pricing
A3: Product Name | B3: Variation | C3: Gram | D3: Discounted Price ($) | E3: Actual Price ($)
A4: Moringa | B4: Moringa | C4: 100g | D4: 11 | E4: 14
A5: Moringa | B5: Moringa | C5: 200g | D5: 21.5 | E5: 28
A6: Moringa 3 + 1 | B6: Moringa | C6: 400g | D6: 35 | E6: 56
A7: Dried Curry Leaves | C7: 30g | D7: 7 | E7: 8.49
A8: Darjeeling Black Tea | C8: 100g | D8: 7.5 | E8: 10
A9: Combo pack | C9: 100g + 30g | D9: 17 | E9: 22.49
A10: Soap | C10: 95g | D10: 7 | E10: 9.49
A11: Moringa + Soap | C11: 100g + 95 | D11: 17 | E11: 23.39
